Traceback (most recent call last):
  File "C:\Users\kimbe\Anaconda3\envs\comp0190\lib\site-packages\jupyter_cache\executors\utils.py", line 56, in single_nb_execution
    record_timing=False,
  File "C:\Users\kimbe\Anaconda3\envs\comp0190\lib\site-packages\nbclient\client.py", line 1204, in execute
    return NotebookClient(nb=nb, resources=resources, km=km, **kwargs).execute()
  File "C:\Users\kimbe\Anaconda3\envs\comp0190\lib\site-packages\nbclient\util.py", line 84, in wrapped
    return just_run(coro(*args, **kwargs))
  File "C:\Users\kimbe\Anaconda3\envs\comp0190\lib\site-packages\nbclient\util.py", line 62, in just_run
    return loop.run_until_complete(coro)
  File "C:\Users\kimbe\Anaconda3\envs\comp0190\lib\asyncio\base_events.py", line 587, in run_until_complete
    return future.result()
  File "C:\Users\kimbe\Anaconda3\envs\comp0190\lib\site-packages\nbclient\client.py", line 664, in async_execute
    cell, index, execution_count=self.code_cells_executed + 1
  File "C:\Users\kimbe\Anaconda3\envs\comp0190\lib\site-packages\nbclient\client.py", line 965, in async_execute_cell
    await self._check_raise_for_error(cell, cell_index, exec_reply)
  File "C:\Users\kimbe\Anaconda3\envs\comp0190\lib\site-packages\nbclient\client.py", line 862, in _check_raise_for_error
    raise CellExecutionError.from_cell_and_msg(cell, exec_reply_content)
nbclient.exceptions.CellExecutionError: An error occurred while executing the following cell:
------------------
with Image.open('media/precipitation_risk.jpg') as img:
    display(img)
------------------

[1;31m---------------------------------------------------------------------------[0m
[1;31mFileNotFoundError[0m                         Traceback (most recent call last)
[1;32m~\AppData\Local\Temp\ipykernel_9804\2998004334.py[0m in [0;36m<module>[1;34m[0m
[1;32m----> 1[1;33m [1;32mwith[0m [0mImage[0m[1;33m.[0m[0mopen[0m[1;33m([0m[1;34m'media/precipitation_risk.jpg'[0m[1;33m)[0m [1;32mas[0m [0mimg[0m[1;33m:[0m[1;33m[0m[1;33m[0m[0m
[0m[0;32m      2[0m     [0mdisplay[0m[1;33m([0m[0mimg[0m[1;33m)[0m[1;33m[0m[1;33m[0m[0m

[1;32m~\Anaconda3\envs\comp0190\lib\site-packages\PIL\Image.py[0m in [0;36mopen[1;34m(fp, mode, formats)[0m
[0;32m   3129[0m [1;33m[0m[0m
[0;32m   3130[0m     [1;32mif[0m [0mfilename[0m[1;33m:[0m[1;33m[0m[1;33m[0m[0m
[1;32m-> 3131[1;33m         [0mfp[0m [1;33m=[0m [0mbuiltins[0m[1;33m.[0m[0mopen[0m[1;33m([0m[0mfilename[0m[1;33m,[0m [1;34m"rb"[0m[1;33m)[0m[1;33m[0m[1;33m[0m[0m
[0m[0;32m   3132[0m         [0mexclusive_fp[0m [1;33m=[0m [1;32mTrue[0m[1;33m[0m[1;33m[0m[0m
[0;32m   3133[0m [1;33m[0m[0m

[1;31mFileNotFoundError[0m: [Errno 2] No such file or directory: 'media/precipitation_risk.jpg'
FileNotFoundError: [Errno 2] No such file or directory: 'media/precipitation_risk.jpg'

